Workbook

Sheet Database
A1: Is dit een kennisvraag voor een specifieke kering of voor alle SVK? 6SSB (overkoepelende vraag voor de 6 stormvloedkeringen), ESB, MSB | B1: Code van de kennisvraag bv RP_ET1 | D1: nummer van de '160 kennisvragenlijst' | F1: omschrijving van de vraag | H1: Impact van het niet weten / beantwoorden van de vraag op de functie waterveiligheid. 0=geen invloed; 1=laag; 2=middel; 3=hoog | I1: Impact van het niet weten / beantwoorden van de vraag op overige functies (scheepvaart, ecologie, sedimenttransport etc.). (0 - 3, 0 geen invloed, 3 is zeer grote invloed) | J1: Impact van het niet weten / beantwoorden van de vraag op budget, planning en uitvoering van BenO. (0 - 3, 0 geen invloed, 3 is zeer grote invloed) | K1: impact van het niet weten/beantwoorden van de vraag op de operatie van sluiten en openen van de kering door het operationeel team. 1=laag; 2=middel; 3=hoog | L1: impact van het niet weten/beantwoorden van de vraag op decision-making at system level and societal support. 1=laag; 2=middel; 3=hoog | M1: zat deze toelichting al in de Excel? | R1: Wanneer is het antwoord op de kennisvraag nodig? Hierbij zijn 4 categorieen gekozen: 0=antwoord levert te weinig op, kennisvraag niet oppakken 1= nu; 2=2033-2040; 3=>2040 | T1: Bij welke onderzoekslijn hoort de kennisvraag primair? Keuze uit (zie tabel 'Onderzoekslijnen) | U1: Bij welke onderzoekslijn hoort de kennisvraag secundair? (zie tabel 'Onderzoekslijnen' | V1: Toelichting keuze onderzoekslijn (niet voor de database voor nu) | W1: Wat is de status van de onderzoekslijn? Wordt dit al opgepakt in een project of programma? Wordt dit een beschrijving of 1 = wordt nog niet opgepakt; 2 = wordt of is gedeelteliik opgepakt; 3=bestaande studie gaat voor de antwoorden zorgen | X1: In welk WP van SSB Delta? | Y1: Zeer grove inschatting van de kosten om de kennisvraag te beantwoorden, inclusief materiaalkosten en aanleg indien relevant | Z1: Hoeveel tijd is nodig om de kennisvraag te beantwoorden? Van het starten aan het werken aan de kennisvraag tot eventuele implementatie in het veld. | AA1: Toelichting status onderzoek (niet voor de database voor nu) | AB1: Toelichting waar moet het belged worden (niet voor de database voor nu) | AC1: Toelichting status, kosten en doorlooptijd studie (niet voor de database voor nu) | AD1: Willen we uiteindelijk ook in de database alle literatuur / documenten opnemen met nummering? Voor later.
A2: SVK | B2: Code | C2: link met andere code (indien relevent) | D2: kennisvraag nummer | E2: keywords kennisvraag | F2: Kennisvraag | G2: Toelichting kennisvraag | H2: Prioriteit: Functie waterveiligheid (uitgedrukt in Failure probability) | I2: Prioriteit: Functies (anders dan waterveiligheid) | J2: Prioriteit: BenO (budget, planning en uitvoering) | K2: Prioriteit: Operatie (OT) | L2: Urgency: Decision-making | M2: toelichting prioriteit / outcome | N2: Outcome category number | O2: Outcome category | P2: impact category number | Q2: impact category | R2: Tijd | S2: toelichting tijd / wanneer antwoord nodig | T2: Onderzoekslijn eerste keus | U2: Onderzoekslijn tweede keus (indien nodig) | V2: toelichting onderzoekslijn | W2: status | X2: Waar belegd | Y2: kosten [euro] | Z2: doorlooptijd [jaren] | AA2: Toelichting status onderzoek (niet voor de database) | AB2: Toelichting waar moet het belged worden | AC2: Toelichting kosten en doorlooptijd studie (niet voor de database) | AD2: relevante documenten
A3: 6SSB | B3: 1_1 | F3: Knowledge management: BSc and MSc projects, and an interdisciplinary summer school | P3: 4 | Q3: =VLOOKUP(Table1[[#This Row],[impact category number]],'Impact categories'!B$3:C$8,2) -> Human capital for a safe and liveable delta | R3: 3 | T3: 9. Organisational aspects | X3: 1
A4: 6SSB | B4: 1_2 | F4: Knowledge disseminiation: Results will be shared via the I-STORM network. Project partners contintue to use and develop the tools and methods, and apply these to international cases. | P4: 5 | Q4: =VLOOKUP(Table1[[#This Row],[impact category number]],'Impact categories'!B$3:C$8,2) -> The Dutch Delta is an example how to deal with climate change in low-lying delta countries and the Dutch water sector remains a frontrunner | R4: 3 | T4: 9. Organisational aspects | X4: 1
A5: ESB, MLB | B5: 3_1 | F5: How do (extreme) local hydraulic loads on the barriers, consisting of water levels, short wave loads (Eastern Scheldt Barrier), and the long wave loads like seiches (Maeslant Barrier), change with changing climate and maintenance/adaptation of the barrier? | H5: 2.5 | I5: 0.4 | J5: 1.7 | K5: 1.7 | L5: 1.1 | P5: 2 | Q5: =VLOOKUP(Table1[[#This Row],[impact category number]],'Impact categories'!B$3:C$8,2) -> Reliable SSBs in technically good condition | R5: 3 | T5: 6. Hydrodynamic effects and loads | X5: 3
A6: 6SSB | B6: 3_2 | F6: What is the structural response of the storm surge barrier to the above hydraulic loads? What are the weakest links and how would the (adapted) barrier respond in more extreme conditions? | H6: 2.4 | I6: 0.2 | J6: 2 | K6: 1.6 | L6: 1.2 | P6: 2 | Q6: =VLOOKUP(Table1[[#This Row],[impact category number]],'Impact categories'!B$3:C$8,2) -> Reliable SSBs in technically good condition | R6: 3 | T6: 1. Structural aspects | U6: 6. Hydrodynamic effects and loads | X6: 3
A7: 6SSB | B7: 3_3 | F7: How to quantify the structural reliability of the storm surge barrier accurately under these changing conditions and thereby reduce conservatism? | H7: 2.4 | I7: 0.3 | J7: 1.8 | K7: 1.3 | L7: 1.5 | P7: 2 | Q7: =VLOOKUP(Table1[[#This Row],[impact category number]],'Impact categories'!B$3:C$8,2) -> Reliable SSBs in technically good condition | R7: 3 | T7: 1. Structural aspects | U7: 6. Hydrodynamic effects and loads | X7: 3
A8: 6SSB | B8: 2.1_1 | F8: What are key uncertainties, ambiguities and tensions in the governance of storm surge barriers? | H8: 1.2222222 | I8: 1.2222222 | J8: 2 | K8: 1.3333333 | L8: 2.2222222 | P8: 3 | Q8: =VLOOKUP(Table1[[#This Row],[impact category number]],'Impact categories'!B$3:C$8,2) -> Well-balanced maintenance and end-of-life decisions for the SSBs by including the system, technical and economical perspective. | R8: 3 | T8: 9. Organisational aspects | X8: 2.1
A9: 6SSB | B9: 2.1_2 | F9: What governance mechanisms facilitate collaborative decision-making of storm surge barriers? | H9: 1.1111111 | I9: 1.3333333 | J9: 1.6666667 | K9: 1.2222222 | L9: 2.4444444 | P9: 3 | Q9: =VLOOKUP(Table1[[#This Row],[impact category number]],'Impact categories'!B$3:C$8,2) -> Well-balanced maintenance and end-of-life decisions for the SSBs by including the system, technical and economical perspective. | R9: 3 | T9: 9. Organisational aspects | X9: 2.1
A10: 6SSB | B10: 2.1_3 | F10: What are suitable tools and methods that can support the governance of storm surge barriers? | H10: 1 | I10: 1.2222222 | J10: 1.8888889 | K10: 1.2222222 | L10: 2.3333333 | P10: 3 | Q10: =VLOOKUP(Table1[[#This Row],[impact category number]],'Impact categories'!B$3:C$8,2) -> Well-balanced maintenance and end-of-life decisions for the SSBs by including the system, technical and economical perspective. | R10: 3 | T10: 9. Organisational aspects | X10: 2.1 | AI10: Opmerkingen: 1. Waar valt optimaliseren sluitregime onder? Bv hoe stroming meenemen in sluitregime, of anders meten en monitoren voor bepalen wel/geen sluiting. Valt onder 4 Maintenance and operation
A11: 6SSB | B11: 2.2_1 | F11: How can we analyse the role of storm surge barriers in wider delta adaptation under uncertain changing conditions? | H11: 2.1111111 | I11: 2.3333333 | J11: 1.4444444 | K11: 1.375 | L11: 2.6666667 | P11: 3 | Q11: =VLOOKUP(Table1[[#This Row],[impact category number]],'Impact categories'!B$3:C$8,2) -> Well-balanced maintenance and end-of-life decisions for the SSBs by including the system, technical and economical perspective. | R11: 3 | T11: 8. System-level adaptation | U11: 10. Remaining lifetime | X11: 2.2
A12: 6SSB | B12: 2.2_1 | F12: How can we connect storm surge barrier functioning with objectives and adaptation in the wider delta system in an uncertain changing climate and socio-economic context? | H12: 2.2222222 | I12: 2.2222222 | J12: 1.3333333 | K12: 1.5555556 | L12: 2.4444444 | P12: 3 | Q12: =VLOOKUP(Table1[[#This Row],[impact category number]],'Impact categories'!B$3:C$8,2) -> Well-balanced maintenance and end-of-life decisions for the SSBs by including the system, technical and economical perspective. | R12: 3 | T12: 8. System-level adaptation | U12: 10. Remaining lifetime | X12: 2.2
A13: 6SSB | B13: 2.2_3 | F13: How to nest decisions for the storm surge barriers in the wider delta system adaptive pathways, and identify pivotal decisions? | H13: 1.7777778 | I13: 2 | J13: 1.7777778 | K13: 1.6666667 | L13: 2.4444444 | P13: 3 | Q13: =VLOOKUP(Table1[[#This Row],[impact category number]],'Impact categories'!B$3:C$8,2) -> Well-balanced maintenance and end-of-life decisions for the SSBs by including the system, technical and economical perspective. | R13: 3 | T13: 8. System-level adaptation | U13: 10. Remaining lifetime | X13: 2.2
A14: 6SSB | B14: 2.2_4 | F14: How can we quantitatively explore multiple pathways for the storm surge barriers within the wider delta system? | H14: 2.25 | I14: 2.3333333 | J14: 1.7777778 | K14: 1.3333333 | L14: 2.5555556 | P14: 3 | Q14: =VLOOKUP(Table1[[#This Row],[impact category number]],'Impact categories'!B$3:C$8,2) -> Well-balanced maintenance and end-of-life decisions for the SSBs by including the system, technical and economical perspective. | R14: 3 | T14: 8. System-level adaptation | U14: 10. Remaining lifetime | X14: 2.2
A15: 6SSB | B15: 2.2_5 | F15: How to analyse multi-dimensional pathways of the complex, interdependent delta system and storm surge barrier elements under deep uncertainty? | H15: 2.3333333 | I15: 2 | J15: 1.5 | K15: 1.25 | L15: 2.6666667 | P15: 3 | Q15: =VLOOKUP(Table1[[#This Row],[impact category number]],'Impact categories'!B$3:C$8,2) -> Well-balanced maintenance and end-of-life decisions for the SSBs by including the system, technical and economical perspective. | R15: 3 | T15: 9. Organisational aspects | U15: 8. System-level adaptation | X15: 2.2
A16: 6SSB | B16: 2.3_1 | F16: How can a decision framework be developed for dynamic maintenance planning at storm surge barriers to ensure reliable operation in an uncertain future? | H16: 2 | I16: 1.2222222 | J16: 2.7777778 | K16: 1.5714286 | L16: 1.375 | P16: 3 | Q16: =VLOOKUP(Table1[[#This Row],[impact category number]],'Impact categories'!B$3:C$8,2) -> Well-balanced maintenance and end-of-life decisions for the SSBs by including the system, technical and economical perspective. | R16: 2 | T16: 4. Maintenance and operation | U16: 8. System-level adaptation | X16: 2.3
A17: 6SSB | B17: 2.3_2 | F17: How and why are the current maintenance plans established, which decision structures are currently active and how do they operate? | G17: How to grasp organisational decision structures? | H17: 1.125 | I17: 0.75 | J17: 2 | K17: 0.75 | L17: 1 | P17: 3 | Q17: =VLOOKUP(Table1[[#This Row],[impact category number]],'Impact categories'!B$3:C$8,2) -> Well-balanced maintenance and end-of-life decisions for the SSBs by including the system, technical and economical perspective. | R17: 2 | T17: 4. Maintenance and operation | U17: 9. Organisational aspects | X17: 2.3
A18: 6SSB | B18: 2.3_3 | F18: Which influences from outside affect the operation and maintenance of storm surge barriers? | G18: How to identify outside influences and their impact for SSB maintenance? How to include adaptive delta system planning? | H18: 1.8333333 | I18: 1.1666667 | J18: 2.3333333 | K18: 1.6666667 | L18: 1.5 | P18: 3 | Q18: =VLOOKUP(Table1[[#This Row],[impact category number]],'Impact categories'!B$3:C$8,2) -> Well-balanced maintenance and end-of-life decisions for the SSBs by including the system, technical and economical perspective. | R18: 2 | T18: 4. Maintenance and operation | U18: 8. System-level adaptation | X18: 2.3
A19: 6SSB | B19: 2.3_4 | F19: What tools or methods are suitable for a decision framework that facilitates a dynamic asset planning? | G19: How to translate complex decision-making mechanisms to decision making frameworks and/or algorithms that facilitate dynamic maintenance planning? | H19: 1.625 | I19: 1.125 | J19: 2.5 | K19: 1.125 | L19: 1.875 | P19: 3 | Q19: =VLOOKUP(Table1[[#This Row],[impact category number]],'Impact categories'!B$3:C$8,2) -> Well-balanced maintenance and end-of-life decisions for the SSBs by including the system, technical and economical perspective. | R19: 2 | T19: 4. Maintenance and operation | U19: 9. Organisational aspects | X19: 2.3
A20: 6SSB | B20: 17 | F20: What is the structural failure probability of the barrier? | G20: Structural failure probability needs to remain below critical level mentioned in the law | P20: 2 | Q20: Reliable SSBs in technically good condition | R20: 1 | T20: 1. Structural aspects | U20: 7. Failure probability | X20: Not included
A21: 6SSB | B21: 2.3_5 | F21: How to apply the decision framework to real SSB case study to arrive at a dynamic asset planning? | G21: We need a convincing case to demonstrate how to arrive at a dynamic asset planning for major maintenance to gain support for outcome and impact. | H21: 1.5 | I21: 1.25 | J21: 2.75 | K21: 1.125 | L21: 1.625 | P21: 3 | Q21: =VLOOKUP(Table1[[#This Row],[impact category number]],'Impact categories'!B$3:C$8,2) -> Well-balanced maintenance and end-of-life decisions for the SSBs by including the system, technical and economical perspective. | R21: 2 | T21: 4. Maintenance and operation | X21: 2.3
A22: ESB, MLB | B22: 3.1_1 | F22: What is the critical loading on the critical barrier elements and how can that best be quantified? ( ESB: wave forces on the gates, MLB: head differences and negative head) | G22: Structural failure probability needs to remain below critical level mentioned in the law | H22: 2.3 | I22: 0.4 | J22: 1.9 | K22: 1.2 | L22: 1 | P22: 2 | Q22: =VLOOKUP(Table1[[#This Row],[impact category number]],'Impact categories'!B$3:C$8,2) -> Reliable SSBs in technically good condition | R22: 2 | T22: 6. Hydrodynamic effects and loads | U22: 1. Structural aspects | X22: 3.1
A23: 6SSB | B23: 3.1_2 | F23: What is the uncertainty in modelled hydrodynamic conditions under extreme storm scenarios (wave conditions and water levels during a 1/10000-year storm)? | H23: 2.2 | I23: 0.3 | J23: 1 | K23: 1.3 | L23: 0.9 | P23: 2 | Q23: =VLOOKUP(Table1[[#This Row],[impact category number]],'Impact categories'!B$3:C$8,2) -> Reliable SSBs in technically good condition | R23: 2 | T23: 6. Hydrodynamic effects and loads | X23: 3.1
A24: 6SSB | B24: 3.1_3 | F24: How does the operational strategy influence the hydrodynamic loads on the barrier? | H24: 2.2 | I24: 0.7 | J24: 1.3 | K24: 2.1 | L24: 1.3 | P24: 2 | Q24: =VLOOKUP(Table1[[#This Row],[impact category number]],'Impact categories'!B$3:C$8,2) -> Reliable SSBs in technically good condition | R24: 2 | T24: 6. Hydrodynamic effects and loads | U24: 4. Maintenance and operation | X24: 3.1
A25: 6SSB | B25: 3.2_2 | F25: Which barrier elements/processes contribute most to the closure failure probability and how could those be optimised to reduce that probability? | H25: 2.4 | I25: 0.3 | J25: 2 | K25: 1.3 | L25: 1.3 | M25: Identifying which elements contribute most to closure failure probability helps refine risk models, informs targeted upgrades, and reduces dominant failure pathways, especially for the Maeslant Barrier where uncertainty is still high. | P25: 2 | Q25: =VLOOKUP(Table1[[#This Row],[impact category number]],'Impact categories'!B$3:C$8,2) -> Reliable SSBs in technically good condition | R25: 2 | T25: 7. Failure probability | X25: 3.2
A26: 6SSB | B26: 3.2_3 | F26: How can we monitor the structural performance? | H26: 1.8 | I26: 0.2 | J26: 2.3 | K26: 0.8 | L26: 0.7 | M26: A better understanding of structural performance under varying conditions directly informs maintenance planning, supports accurate flood‑risk calculations, and clarifies which monitoring methods meaningfully improve the reliability of the barrier | P26: 2 | Q26: =VLOOKUP(Table1[[#This Row],[impact category number]],'Impact categories'!B$3:C$8,2) -> Reliable SSBs in technically good condition | R26: 2 | T26: 1. Structural aspects | X26: 3.2
A27: 6SSB | B27: 3.2_4 | F27: How do changes in boundary conditions affect structural response, condition, and the interpretation of monitoring outcomes? | H27: 2 | I27: 0.5 | J27: 2.1 | K27: 1.3 | L27: 0.8 | M27: Changes in boundary conditions (waves, water levels, wind) affect structural response and monitoring interpretation. Understanding this is important to shape future maintenance planning. | P27: 2 | Q27: =VLOOKUP(Table1[[#This Row],[impact category number]],'Impact categories'!B$3:C$8,2) -> Reliable SSBs in technically good condition | R27: 3 | T27: 4. Maintenance and operation | U27: 10. Remaining lifetime | X27: 3.2
A28: 6SSB | B28: 3.2_1 | F28: How to monitor the structural health and performance under changing use and conditions? How can monitoring be used to evaluate deviations from design assumptions, modelled scenarios, and adaptation pathways, enabling timely adjustment of maintenance and adaptation actions? | H28: 2 | I28: 0.4 | J28: 2.4 | K28: 1.1 | L28: 0.9 | M28: Monitoring can contribute to enabling more efficient maintenance planning and extend component lifetimes. | P28: 2 | Q28: =VLOOKUP(Table1[[#This Row],[impact category number]],'Impact categories'!B$3:C$8,2) -> Reliable SSBs in technically good condition | R28: 2 | T28: 1. Structural aspects | U28: 10. Remaining lifetime | X28: 3.2
A29: ESB | B29: 3.3_1 | F29: Which main failure mechanism (failure to close, structural failure or hydraulic overload) is dominant for the Eastern Scheldt barrier? And how does that change with (up to 0.5m) sea level rise and economic development in the coming 50 years? | H29: 2.3 | I29: 0.4 | J29: 1.8 | K29: 1.3 | L29: 1.9 | P29: 2 | Q29: =VLOOKUP(Table1[[#This Row],[impact category number]],'Impact categories'!B$3:C$8,2) -> Reliable SSBs in technically good condition | R29: 3 | T29: 10. Remaining lifetime | X29: 3.3
A30: ESB | B30: 3.3_2 | F30: How to adapt the Eastern Scheldt barrier in a systematic risk-based manner? | H30: 2.4 | I30: 0.8 | J30: 1.8 | K30: 1.6 | L30: 2.1111111 | P30: 2 | Q30: =VLOOKUP(Table1[[#This Row],[impact category number]],'Impact categories'!B$3:C$8,2) -> Reliable SSBs in technically good condition | R30: 3 | T30: 10. Remaining lifetime | U30: 8. System-level adaptation | X30: 3.3
A31: 6SSB | B31: 4.1_4 | F31: What is the erosion of tidal flats and how will these erosion trends develop in the future? | G31: Is the erosion of tidal flats finding an equilibrium? What are the morphological developments of the tidal channels? What factors contribute most to erosion of tidal flats (SLR, altered hydrodynamics due to the barrier)? Is there a correlation between erosion of the tidal flats (loss in intertidal area) and the loss in species (benthic fauna, waders) numbers? | H31: 1.1 | I31: 2.6 | J31: 1.3 | K31: 0.6 | P31: 3 | Q31: =VLOOKUP(Table1[[#This Row],[impact category number]],'Impact categories'!B$3:C$8,2) -> Well-balanced maintenance and end-of-life decisions for the SSBs by including the system, technical and economical perspective. | R31: 2 | T31: 8. System-level adaptation | X31: 4.1
A32: 6SSB | B32: 4.1_1 | F32: What does an increased closing frequency as a result of SLR and/or alternative barrier management mean for the morphology of the hinterland? | G32: Is there significant morphological development due to expected closure frequencies? (If so, what are tipping points?) | H32: 1.7272727 | I32: 2.6363636 | J32: 1.4545455 | K32: 1.0909091 | P32: 1 | Q32: =VLOOKUP(Table1[[#This Row],[impact category number]],'Impact categories'!B$3:C$8,2) -> SSBs contribute to satisfying socio-economic and environmental needs in the hinterland | R32: 2 | T32: 8. System-level adaptation | X32: 4.1
A33: 6SSB | B33: 4.1_3 | F33: How do storm surge barriers affect channel and delta morphology? | G33: What are is the morphological equilibrium the delta system develops toward without presences of SSB's? How do SSB's (and other flood risk measures/delta management practices) alter this natural equilibrium? How will the morphological processes (e.g. erosion, aggradation) change with future SLR and boundary conditions? And other way around: How do changes in channel morphology affect SSB (decisions)? | H33: 1.7272727 | I33: 2.5454545 | J33: 1.1818182 | K33: 0.81818182 | P33: 1 | Q33: =VLOOKUP(Table1[[#This Row],[impact category number]],'Impact categories'!B$3:C$8,2) -> SSBs contribute to satisfying socio-economic and environmental needs in the hinterland | R33: 3 | T33: 8. System-level adaptation | X33: 4.1
A34: 6SSB | B34: 4.1_2 | F34: Are there morphological alterations/developments within the system that alter the flood risk (and with that flood risk management)? | H34: 2.0909091 | I34: 1.6363636 | J34: 1.2727273 | K34: 0.90909091 | P34: 1 | Q34: =VLOOKUP(Table1[[#This Row],[impact category number]],'Impact categories'!B$3:C$8,2) -> SSBs contribute to satisfying socio-economic and environmental needs in the hinterland | R34: 3 | T34: 8. System-level adaptation | X34: 4.1
A35: 6SSB | B35: 18 | F35: How can the structure (or assessment) be adapted such that the probability decreases . (measure to update an insufficient barrier). | G35: Structural failure probability needs to remain below critical level mentioned in the law | P35: 2 | Q35: Reliable SSBs in technically good condition | R35: 2 | T35: 1. Structural aspects | X35: Not included
A36: 6SSB | B36: 4.1_5 | F36: How is water quality altered with changing future boundary conditions? | G36: What is the water quality due to water temperature increase? How does salinization and salt intrusion in the water system progress with future boundary conditions. What are the effects for water quality for future systems ecology (vegetation, benthic fauna). | H36: 0.18181818 | I36: 2.3636364 | J36: 1 | K36: 0.45454545 | P36: 3 | Q36: =VLOOKUP(Table1[[#This Row],[impact category number]],'Impact categories'!B$3:C$8,2) -> Well-balanced maintenance and end-of-life decisions for the SSBs by including the system, technical and economical perspective. | R36: 2 | T36: 8. System-level adaptation | X36: 4.1
A37: 6SSB | B37: 32 | F37: How to quantify the change in functional performance of the barrier? | G37: Uncertain how SLR influences the functional performance of the barrier | P37: 1 | Q37: SSBs contribute to satisfying socio-economic and environmental needs in the hinterland | R37: 3 | T37: 10. Remaining lifetime of existing objects | X37: Not included
A38: 6SSB | B38: 48 | F38: What is the required dike reinforcement (spatial footprint) and costs in combination with the SSB strategy? | P38: 3 | Q38: Well-balanced maintenance and end-of-life decisions for the SSBs by including the system, technical and economical perspective. | R38: 3 | T38: 4. Maintenance and operation | U38: 8. Adaptation system level | X38: Not included
A39: 6SSB | B39: 45 | F39: What functions/stakeholders/sectors should the SSBs and water system support in the future | P39: 1 | Q39: SSBs contribute to satisfying socio-economic and environmental needs in the hinterland | R39: 3 | T39: 10. Remaining lifetime | X39: Not included
A40: 6SSB | B40: 46 | F40: How do public and political perspectives on SSB adaptation align or diverge, and what are implications for decision-making? | P40: 3 | Q40: Well-balanced maintenance and end-of-life decisions for the SSBs by including the system, technical and economical perspective. | R40: 3 | T40: 9. Organisational aspects | U40: 8. Adaptation system level | X40: Not included
...

Sheet Research lines
B2: Number | C2: Research line
B3: 1 | C3: 1. Structural aspects
B4: 2 | C4: 2. Control systems and industrial automation
B5: 3 | C5: 3. Facilities and buildings
B6: 4 | C6: 4. Maintenance and operation
B7: 5 | C7: 5. Cyber and security
B8: 6 | C8: 6. Hydrodynamic effects and loads
B9: 7 | C9: 7. Failure probability
B10: 8 | C10: 8. System-level adaptation
B11: 9 | C11: 9. Organisational aspects
B12: 10 | C12: 10. Remaining lifetime

Sheet Outcome categories
B2: Outcome number | C2: Outcome category | D2: Link to impact number | E2: Impact category
C3: staat dit in het voorstel benoemd? | D3: 1 | E3: =VLOOKUP(D3,'Impact categories'!B$2:C$7,2) -> SSBs contribute to satisfying socio-economic and environmental needs in the hinterland
D4: 1 | E4: =VLOOKUP(D4,'Impact categories'!B$2:C$7,2) -> SSBs contribute to satisfying socio-economic and environmental needs in the hinterland
D5: 1 | E5: =VLOOKUP(D5,'Impact categories'!B$2:C$7,2) -> SSBs contribute to satisfying socio-economic and environmental needs in the hinterland
D6: 2 | E6: =VLOOKUP(D6,'Impact categories'!B$2:C$7,2) -> Reliable SSBs in technically good condition
D7: 2 | E7: =VLOOKUP(D7,'Impact categories'!B$2:C$7,2) -> Reliable SSBs in technically good condition
D8: 2 | E8: =VLOOKUP(D8,'Impact categories'!B$2:C$7,2) -> Reliable SSBs in technically good condition
D9: 3 | E9: =VLOOKUP(D9,'Impact categories'!B$2:C$7,2) -> Well-balanced maintenance and end-of-life decisions for the SSBs by including the system, technical and economical perspective.
D10: 3 | E10: =VLOOKUP(D10,'Impact categories'!B$2:C$7,2) -> Well-balanced maintenance and end-of-life decisions for the SSBs by including the system, technical and economical perspective.
E11: =VLOOKUP(D11,'Impact categories'!B$2:C$7,2) -> #N/A
E12: =VLOOKUP(D12,'Impact categories'!B$2:C$7,2) -> #N/A
E13: =VLOOKUP(D13,'Impact categories'!B$2:C$7,2) -> #N/A
E14: =VLOOKUP(D14,'Impact categories'!B$2:C$7,2) -> #N/A
E15: =VLOOKUP(D15,'Impact categories'!B$2:C$7,2) -> #N/A
E16: =VLOOKUP(D16,'Impact categories'!B$2:C$7,2) -> #N/A
E17: =VLOOKUP(D17,'Impact categories'!B$2:C$7,2) -> #N/A
E18: =VLOOKUP(D18,'Impact categories'!B$2:C$7,2) -> #N/A

Sheet Impact categories
B2: Number | C2: Impact category | D2: Explanation
B3: 1 | C3: SSBs contribute to satisfying socio-economic and environmental needs in the hinterland | D3: The storm surge barriers contribute to satisfying the socio-economic and environmental needs in the hinterland. This implies that people, knowledge, data, and tools are available to determine what thehinterland requires from the storm surge barrier. These requirements will likely evolve over time due to changes in sea-level as well as changes in society.
B4: 2 | C4: Reliable SSBs in technically good condition | D4: The storm surge barrier is reliable and in a good technical condition. The barrier is properly monitored and methods are available to determine the technical condition. Methods like an adaptive maintenance planning and people are available for timely decisions on maintenance and reinforcement of (parts of) the storm surge barrier in relation to the needs from the hinterland.
B5: 3 | C5: Well-balanced maintenance and end-of-life decisions for the SSBs by including the system, technical and economical perspective. | D5: A well-balanced maintenance is enabled and end-of-lifetime decision for the storm surge barriers can be made by including the system, technical and economical perspective. A time-based adaptive pathway is available to determine when a storm surge barrier reaches its end of life (functional and structural) and what the options and impacts are for maintenance, removal, replacement, closure. Supporting near-future decision making and avoiding maladaptation.
B6: 4 | C6: Human capital for a safe and liveable delta | D6: Human capital for a safe and liveable delta. There is a knowledgeable community of professionals that is enabled to cope with the challenges in deltas.
B7: 5 | C7: The Dutch Delta is an example how to deal with climate change in low-lying delta countries and the Dutch water sector remains a frontrunner | D7: The Dutch Delta is an example how to deal with climate change in low-lying delta-countries and the Dutch Water sector remains a frontrunner. Knowledge and experience are shared in an inclusive international community with organizations and countries facing similar climate challenges.
