Workbook

Sheet MetaData
B2: Deltares/RWS Projectnaam: Kennisvragen Sluizen met uitwerking voor Sluis Panheel Datum: 12-08-2026 Auteurs: Deltares: Meinard Tiessen Esther van Baaren Rijkswaterstaat: Riva de Vries Iris Koekkoek Betrokkenen Rijkswaterstaat: Martine Jak-Brinkhuis Patrizia Bernardini Evelien Ploos Van Amstel Peter Jansen Wilco Meijerink Max Pouwels Assetmanagementteam RWS: Linneke van der Veeken Michel de Waal Kees corstens Carla Sengers Paul van Wijnkel Kees van Rooij Carina Verbeek Denise Buijk Jos Hendriks Betrokkenen TNO: Greta van Velzen Esra Bektas Betrokkenen Deltares: Tom Omahoney

Sheet Systeem
B1: Ligging sluiscomplex Panheel:
B2: Het sluiscomplex Panheel ligt in het kanaal Wessem-Nederweert (KWN), nabij de plaats Panheel. Het KWN is een 17 km lange vaarweg die de Maas verbindt met de Zuid-Willemsvaart en Noordervaart (bij Nederweert). Het hele kanalenstelsel wordt gevoed met Maaswater vanuit de Maas bij St Pieter. In natte periodes wordt het kanaal gevoed door lokale afloop, maar bij waterschaarste op de Maas kan deze ook worden gevoed via het gemaal bij Sluizencomplex Panheel. Het kanaal Wessem-Nederweert (KWN) staat in open verbinding met de Zuid-Willemsvaart en staat middels Sluizencomplex Panheel in verbinding met de Maas. De waterstand in het kanaal is hoger dan de waterstand in de Maas. Nabij het kanaal bevinden zich enkele beken die onder het kanaal doorstromen door middel van een sifon. Dit zijn de Tungelroyse Beek en de Uffelse Beek.
B4: Proces/ operatie van complex Panheel :
B5: Op het Sluiscomplex Panheel wordt geschut in de oude en nieuwe sluis.
B6: Bij een overschot aan Maaswater op het KWN wordt geschut met de nieuwe sluis (meer schutverlies)en gespuid via de nieuwe sluis buiten bedientijden (’s nachts).
B7: Bij te weinig aanvoer van Maaswater op het KWN wordt geschut met de oude sluis, wordt schutverlies beperkt door de spaarbekkens te gebruiken en/of zuinig te schutten (wachten tot de schutkolk vol schepen is), en/of wordt Maaswater gepompt naar het kanaal door het gemaal.
B8: De bediening vindt centraal plaats vanuit de bedienpost in Tilburg, maar kan ook vanaf de bedienpost aan de zuidzijde van het complex worden bediend. Hiervandaan worden beide sluizen en het gemaal bediend. Het nivelleren van de oude sluis (zonder spaarbekkens) duurt 7 tot 8 minuten, in de nieuwe sluis ca. 10 minuten.
B10: Functies van sluiscomplex Panheel:
B11: Schutfunctie: een bijdrage leveren aan de mogelijkheid om de scheepvaart binnen een bepaalde normtijd waterpanden te laten passeren. De schutsluizen leveren deze bijdrage door de scheepvaart binnen een bepaalde schuttijd een waterstandsverschil te laten overbruggen.
B12: Peilbeheer. Daarbij kan onderscheid gemaakt worden in de volgende subfuncties: Keren, spuien/ doorlaten water, schutverlies beperken dmv spaarbekkend en water pompen.
B13: Keerfunctie: de schutsluizen en het gemaal keren het niveauverschil tussen het KWN en de Maas. Op basis van de maatgevende waterstanden is er alleen sprake van keren waarbij het KWN-niveau hoger is dan het Maasniveau. Het sluizencomplex heeft zelf geen kerende functie.
B14: Spuifunctie: de nieuwe schutsluis wordt buiten de bedientijden ingezet om overtollig water af te voeren van het KWN. | M14: SchutSluizencomplex Panheel noord (oude kolk) 58C-001-01​
B15: Schutverlies beperkingfunctie: de spaarbekkens van de oude schutsluis worden in tijden van droogte gebruikt om het niveau op het kanalenstelsel zo min mogelijk te laten dalen. | M15: Sluizencomplex Panheel noord in het kanaal Wessem-Nederweert​
B16: Waterpompfunctie: het gemaal wordt in tijden van droogte gebruikt om water aan te voeren naar het kanalenstelsel. | M16: Limburg - Maasgouw
B18: De functie schutverlies beperken is in deze analyse alleen kwalitatief beschouwd.
B19: De bediening van Sluiscomplex Panheel zal naar verwachting in 2015 worden ondergebracht in de bediencentrale te Tilburg. Deze ontwikkeling is niet meegenomen in de analyse. | D19: Bron: E60-WKR-KA-1300035 - Rapport integrale RAMS analyse_Sluiscomplex Panheel_v4.0.pdf
B22: Zie document: Beschrijving_sluiscomplex_Panheel_(tabblad_1).docx
B26: Overzicht functies van systeem tot en met complex niveau
B27: Water vasthouden (peilbeheer)
B28: Keren water (waterveiligheid, kanaalzijde oevers tot aan de sluis, niet de sluis zelf)
B29: Spuien water/ Afvoeren van overtollig water (peilbeheer)
B30: Schutverlies beperken dmv spaarbekkens (peilbeheer)
B31: Water pompen (peilbeheer)
B32: Peilbeheer: Schutverlies beperken dmv spaarbekkens
B33: Waterkwaliteit
B34: Ecologie
B35: Cultuurhistorische waarde
B36: Faciliteren scheepvaart
... B53: De CEMT-klasse op het kanaal is klasse II (lengte 96 m, breedte 9,5 m, max. diepgang 2,10 m). De recreatievaartklasse is BM (ontsluiting voor motorboten). De nieuwe sluis is geschikt voor schepen t/m klasse II. Door de oude sluis kunnen alleen schepen tot 7,25 m breed. Uit interviews blijkt dat er eens per 14 dagen een schip passeert, dat te breed is voor de oude sluis.

Sheet Sluizencomplex
B1: Het Complex
B2: Het sluizencomplex Panheel heeft met bijna 8 meter het op twee na grootste verval van alle sluizen in Nederland. Het complex omvat een gemaal en twee sluizen: de oude, noordelijke sluis (gebouwd tussen 1925 en 1928, gerenoveerd in 1995) en de nieuwe, zuidelijke sluis ernaast (gebouwd tussen 1986 en 1992).
B3: De oude, noordelijke sluis is voor Nederland uniek in zijn soort. Naast de oude sluis liggen twee spaarbekkens en twee andere bassins zijn in de betonnen sluiswand uitgespaard. Door gebruik van deze spaarbekkens is het mogelijk ongeveer 60% van het water te besparen tijdens het schutproces (figuur 12). Dimensies van de oude sluis zijn 150 meter lang, 7,5 meter breed en 11,5m meter diep. De drempel diepte van de benedenkant (buiten) is -2,90 meter. De drempel diepte van de bovenkant (binnen) is -3,15 meter.
B4: De nieuwe, zuidelijke sluis, waaraan van 1986 tot 1992 is gebouwd, is aanzienlijk breder dan de oude (150 meter lang, 12,6 meter breed en 11,5 meter diep), waardoor deze geschikt is tot CEMT klasse IV schepen. (figuur 6). De drempel diepte van de benedenkant (buiten) is -4,20 meter. De drempel diepte van de bovenkant (binnen) is -3,95 meter.
B5: Naast het sluiscomplex is een pompgemaal gerealiseerd. Twee elektrische pompen met een vermogen van 440 kW elk, zorgen er eventueel voor dat het bij het schutten verloren gegane water wordt teruggepompt.
B6: De bediening van de twee sluizen en het gemaal vindt centraal plaats maar kan ook vanuit een bediengebouw dat zich aan de zuidzijde van de nieuwe sluis bevindt.
B7: Het gemaal bestaat uit de volgende onderdelen: 1. Instroomgedeelte en gemaal; 2. Gesloten koker; 3. Uitstroomgedeelte (let wel: Noord is naar onder): (figuur 8)
J10: Bron: RWSZN-2022-022938_Oudesluis_functioneren_spaarbekkens_incl_hoogtes.pdf
B25: Bron: E60-WKR-KA-1300035 - Rapport integrale RAMS analyse_Sluiscomplex Panheel_v4.0.pdf
B28: Zie document: Beschrijving_sluiscomplex_Panheel_(tabblad_1).docx
B31: Hydraulische randvoorwaarden - waterbeheer:
B33: Kanaal Wessem Nederweert (ten westen / noordwesten van het complex)
B34: Streefpeil /SP 28.65 m +NAP
B35: Minimaal Waterpeil /MIP1 28.52 m + NAP
B36: Minimaal Waterpeil /MIP2 28.40 m +NAP
B37: Maximaal Waterpeil /MAP1 28.70 m +NAP
B38: Maximaal Waterpeil /MAP2 28.72 m +NAP
B39: Waterstanden bij vullen en ledigen kolk met gebruik van spaarkomen;
B41: Stuwpand Linne (ten oosten / zuidoosten van het complex)
B42: Streefpeil /SP 20.85 m +NAP
... B45: Bron: Bijlage V streefpeilen

Sheet Complex-object 
A1: Complex | B1: Type functies complex | C1: Functies complex | D1: Eisen/wensen complex | E1: Object | F1: Functie object | G1: Eisen/wensen object | H1: Opmerkingen over eisen/wensen en relevantie voor functioneren sluis Panheel | I1: Bron
A2: Sluiscomplex als samenhangend geheel, opgebouwd uit meerdere componenten, bestaande uit twee schutsluizen en een pompgemaal. | B2: Peilbeheer en waterveiligheid | C2: Water vasthouden (peilbeheer) | D2: Het complex draagt bij aan het handhaven van gewenste waterstanden en debieten in het watersysteem Maas – Kanaal Wessem–Nederweert, onder zowel natte als droge omstandigheden. | E2: Sluiscomplex Panheel | F2: Handhaven van peilscheiding en sturen van waterstanden tussen Maas en KWN door: water te keren, water te spuien of door te laten, water actief terug te pompen, schutverlies te beperken De oude sluis functioneert als spaarsluis ten behoeve van waterbesparing. | G2: Stabiel streefpeil KWN | H2: Peilbeheer is een kernfunctie van Sluis Panheel. De combinatie van schutten, pompen en spaarbekkens maakt het complex strategisch voor zoetwaterverdeling richting het Brabantse kanaalsysteem. | I2: Basisspecificatie SS/ RINK
G3: Beperking van zoetwaterverlies bij schutten
G4: Voldoende zoetwater vasthouden tijdens droogte
C5: Keren water (waterveiligheid, kanaalzijde oevers tot aan de sluis, niet de sluis zelf) | D5: De schutsluizen en het gemaal keren het niveauverschil tussen het KWN en de Maas. Op basis van de maatgevende waterstanden is er alleen sprake van keren waarbij het KWN-niveau hoger is dan het Maasniveau. | E5: Sluiscomplex Panheel | F5: Keren hoogwater in gesloten stand. | G5: Streefpeil KWN: +28.65 en Maas MLW: +20.70 . Sluis Panheel houdt waterstandsverschillen tegen (± 7–8 m verval) | H5: Keren van hoogwater als het KWN-niveau hoger is dan bij het Maasniveau (beschermen tegen hoogwater vanuit bovenstrooms of benedenstrooms). De kerende functie kan bij beide sluizen als volgt falen: - Indien de sluis gesloten is kan dit gebeuren als beide hoofden niet meer keren, bijvoorbeeld doordat een deur of schuif bezwijkt. Indien de deuren bij het ene hoofd geopend zijn voor schutten, kan falen van het andere hoofd leiden tot een doorstroom opening, bijvoorbeeld door aanvaring in combinatie met falen van de aanvaarbescherming. - Bij het spuien in de nieuwe sluis kan de kerende functie ook falen indien de bedienaar per abuis een te grote spui-opening realiseert. Bij het spuien buiten bedientijd (’s nachts) wordt de waterstand gemonitord en het falen dus met enige vertraging geconstateerd. | I5: Basisspecificatie SS/ RINK
G6: Betrouwbaar sluiten bij hoogwater
G7: Geen formele faalkansnorm, wel hoge functionele betrouwbaarheid
C8: Spuien water/ Afvoeren van overtollig water (peilbeheer) | D8: Voldoende afvoeren hoog rivierdebiet om substantiële verhoging van hydraulische belasting op achterliggende primaire waterkeringen te voorkomen | E8: Sluiscomplex Panheel | F8: Afvoeren (hoog) rivierdebiet | G8: Spuifunctie: de nieuwe schutsluis wordt buiten de bedientijden ingezet om overtollig water af te voeren van het KWN. | H8: Spuien via de nieuwe sluis gebeurt meestal buiten de bedientijden (’s nachts) en vrijwel nooit op dagen dat het gemaal wordt gebruikt. Er wordt regelmatig ook nog overdag gespuid in bedientijd. Dit gebeurt naar schatting op 75% van de spuidagen en duurt gemiddeld 2 à 3 uur. Het spuiriool in de oude sluis heeft te weinig afvoercapaciteit voor de gebruikelijke spuibehoefte. Bij spuien in de nieuwe sluis worden de deurschuiven gedeeltelijk open gezet. Dergelijke schuiven worden in het schutproces altijd geheel geopend, niet gedeeltelijk. Het langdurig gedeeltelijk open staan van de schuiven levert mogelijk te zware belastingen op. | I8: Basisspecificatie SS/ RINK
B9: Leefbaarheid | C9: Schutverlies beperken dmv spaarbekkens (peilbeheer) | D9: Peilbeheer is een kernfunctie van Sluis Panheel. Met name in droogteperioden is de combinatie van schutten, spaarbekkens en pompen cruciaal voor het vasthouden en verdelen van zoetwater richting het Brabantse kanaalsysteem. | E9: Sluiscomplex Panheel | F9: Beperking van (zoetwater)verlies bij schutten | G9: Voldoende zoetwater vasthouden tijdens droogte | H9: De spaarbekkens van de oude schutsluis zijn op dit moment niet in gebruikt, maar zijn ontworpen om het niveau op het kanalenstelsel zo min mogelijk te laten dalen. 60% van schutwater kan worden hergebruikt middels de spaarbekkens. Dit is bedoeld om zoetwaterverlies te beperken in perioden van waterschaarste. | I9: Rams analyse/ ontw RVW ss
G10: Voldoende vaardiepte voor scheepvaart waarborgen
C11: Water pompen (peilbeheer) | D11: Door middel van pompcapaciteit kan onder droge omstandigheden water worden aangevoerd naar het kanalenstelsel, zodat gewenste peilen en watervoorziening gehandhaafd blijven. Het complex moet flexibel kunnen inspelen op variaties in rivierafvoer en veranderende hydrologische omstandigheden. | E11: Sluiscomplex Panheel | F11: Flexibel inspelen op variaties in rivierafvoer (nat/droog) | G11: Mogelijkheid tot actief waterbeheer bij droogte (inzet pomgemaal). | H11: Het gemaal wordt in tijden van droogte gebruikt om water aan te voeren naar het kanalenstelsel. Afhankelijk van weersomstandigheden is er veel verschil in de frequentie en duur van de operatie; soms wordt er wel tot 4 dagen continu gepompt. De maximale stilstandduur is ca. 2 maanden. Voor het bedieninterval wordt 1 maand gehanteerd. De kerende functie kan falen bij het gemaal wanneer aan het eind van het verpompen zowel de persschuif als de vlinderklep op 1 watergang niet sluiten. Bij energie-uitval sluit een vlinderklep niet ofwel als de black-out klep gesloten blijft (en de hydraulische druk dus niet wegvalt) ofwel als de overbrenging van het contragewicht faalt doordat de spie van de as afbreekt. | I11: Rams analyse/ ontw RVW ss
C12: Waterkwaliteit | D12: Geen verslechtering van waterkwaliteit in de sluis en kanaalbeheer; voldoen aan KRW-doelen. | E12: Sluiscomplex Panheel | F12: Bijdragen aan doorstroming en voorkomen van stagnatie. | G12: Bedieningsregime afgestemd op (voldoende) doorstroming | H12: Randvoorwaardelijke functie; niet primair sturend voor ontwerp, maar relevant voor beheer en bediening. | I12: Basisspecificatie SS
G13: Geen langdurige stilstand van watermassa’s
C14: Ecologie | D14: Behoud en waar mogelijk versterking van ecologische kwaliteit; voldoen aan Natura 2000 / KRW-ecologische doelen (waar relevant). | E14: Sluiscomplex Panheel | F14: Faciliteren van ecologische verbindingen en minimaliseren van negatieve effecten op habitats en soorten. | G14: Behouden van geschikt habitat in en rond het complex. Voorkomen van verstoring. | H14: Randvoorwaardelijke functie; niet primair sturend voor ontwerp, maar relevant voor beheer en bediening. Meekoppelkansen mogelijk bij onderhoud en aanpassing (bijv. vispassage of ecovriendelijke inrichting).
C15: Cultuurhistorische waarde | D15: Borging en herkenbaarheid van cultuurhistorisch waardevolle onderdelen van het complex. | E15: Sluiscomplex Panheel | F15: Drager van cultuurhistorische en historische waarden. | G15: Rekening houden met monumentale en cultuurhistorische waarden | H15: De oude sluis (gebouwd in 1925–1928) heeft cultuurhistorisch belang en een oranje status, wat betekent dat er wel waarde is, maar geen formele monumentenbescherming. | I15: Bouwhistorische verkenning & waardestelling sluis panheel kanaal wessem nederweert 22 maart 2022
G16: Behoud van karakteristieke constructieve en ruimtelijke kenmerken
G17: Beperkingen aan aanpassing, vervanging of buitengebruikstelling van de oude sluis
B18: Bereikbaarheid | C18: Faciliteren scheepvaart | D18: Betrouwbare en vlotte doorvaart tussen Maas en Kanaal Wessem–Nederweert. | E18: Sluiscomplex Panheel (Oude, noordelijke sluis en nieuwe, zuidelijke sluis) | F18: De schutsluis dient het maatgevende schip CEMT klasse 2 te kunnen laten passeren. Efficiënt schutproces. | G18: De oude, noordelijke sluis en nieuwe, zuidelijke sluis faciliteren beiden CEMT-klasse 2-scheepvaart. De oude sluis faciliteert schepen tot maximaal 7,25 meter breed, de nieuwe sluis faciliteerd schepen tot 9,5 meter breed. Recreatievaart tot en met categorie BM. | H18: Door de oude sluis kunnen alleen schepen tot 7,25 m breed. Uit interviews blijkt dat er eens per 14 dagen een schip passeert, dat te breed is voor de oude sluis. | I18: RAMS-analyse
G19: Voldoende vaardiepte voor scheepvaart waarborgen. Maatgevende afmetingen van circa 95 × 7,25 m en een maximale diepgang van circa 2,10 m.
G20: Beschikbaarheid van (minimaal) één kolk. | H20: Nut en noodzaak van twee kolken is onderwerp van heroverweging (kennisagenda).
D21: De schutsluis dient het scheepvaartaanbod vlot en veilig te kunnen schutten. | E21: Sluiskolken | F21: Schutfunctie (grote, kleine en recreatie schepen) | G21: De oude, noordelijke sluis en nieuwe, zuidelijke sluis faciliteren beiden CEMT-klasse 2-scheepvaart. Recreatievaart tot en met categorie BM. | H21: Schutten wordt gestaakt bij ijsgang, bij gevaarlijke situaties, of indien het peilbeheer dit vereist. Bij ijsgang is er geen watertekort, de functie verpompen wordt hierdoor dus niet gehinderd. | I21: RAMS-analyse
G22: Acceptabele wachttijden
G23: De schutsluis dient waterpeil te nivelleren, waarbij een rustige ligging van de schepen wordt verzekerd.
B24: Overige functies | C24: Faciliteren van de bediening | D24: Betrouwbare, veilige en robuuste bediening. | E24: Sluiscomplex Panheel | F24: Bediening op afstand (middels een interface bediencommando's geven); ondersteunen bieden aan beheer en onderhoud. | G24: Betrouwbare ICT en energievoorziening | H24: Het falen van een onderdeel uit de bediening en besturing is ofwel centraal, met hinder voor alle functies passeren/spuien/verpompen, ofwel lokaal. | I24: Basisspecficatie SS/ RINK
G25: Cybersecurity
G26: Ondersteuning inspectie en onderhoud
C27: Calamiteiten | D27: Ondersteunen robuust functioneren watersysteem bij verstoringen. | E27: Sluiscomplex Panheel | F27: Beschikbaarheid bij calamiteiten elders in het systeem. | G27: Flexibel inzetbaar (spuien, pompen en sluiten) en redunantie. | H27: Redundantie via twee kolken is onderwerp van afweging.

Sheet Driver-overzicht
A1: Categorie | B1: Type / Driver | C1: Toelichting | D1: Informatie en verandering | E1: Verwachte relevantie voor Object Sluizencomplex Panheel | F1: Toelichting | G1: Bron | H1: Samenhang andere NK's | J1: De schaal van relevantie (impact op het kunstwerk)
A2: Autonome situatie | B2: Huidige (en ontwerp) staat | C2: Wat waren/zijn de uitgangsposities van het ontwerp van Sluizencomplex Panheel en weten we wat de status nu is? (aldus Ontw RVW SS: belasting: waterstand, windopzet, schutgolven, scheepsgolven, combinatie) | D2: Ontwerp gebaseerd op binnenvaart, peilbeheer en waterverdeling tussen Maas en kanaalsysteem. Belastingen bestaan uit waterstandsverschillen, schutwerkingen, scheepsbelasting en mechanische belasting van bewegingswerken (geen windopzet/golfbelasting vanuit zee). | E2: Groot | F2: Sluizencomplex Panheel is een actief waterstaatkundig object met continue wisselende belastingen door schutten en peilbeheer; dit vormt de basis voor alle verdere verouderings- en faalmechanismen. | G2: Expert kennis RWS | J2: Klein | K2: Verwaarloosbare driver
B3: Vermoeiing | C3: Afname sterkte door (af)wisselende belasting (periodieke belasting op de stalen delen, bijvoorbeeld door golven in combinatie met de waterstand) | D3: Met name relevant voor deuren, aandrijvingen en staalconstructies door hoge schutfrequentie en cyclische belasting. | E3: Mogelijk groot | F3: In tegenstelling tot keringen met incidentele belasting treedt bij Panheel continue vermoeiing op. Dit maakt vermoeiingsschade een belangrijk aandachtspunt voor levensduur en onderhoudsstrategie. | G3: Expert kennis TNO | J3: Mogelijk klein | K3: Nog onbekend welke invloed de driver precies heeft; minder prioriteit om uit te zoeken
B4: Slijtage | C4: Eroderen (slijten) van materialen door het inzetten van de sluis | D4: Slijtage door schutten en bewegende delen is structureel aanwezig maar beheersbaar met regulier onderhoud. | E4: Mogelijk klein | F4: Hoewel slijtage continu optreedt, is deze bij tijdig onderhoud goed te beheersen. Het vormt vooral een aandachtspunt bij uitstel van onderhoud of intensiever gebruik. | G4: Expert kennis TNO | J4: Middel | K4: Relevante driver
B5: Schade (aanvaar, temperatuursinvloeden) | C5: Calamiteit die zorgt voor lokale schade/verzwakking. | D5: Aanvaringen en storingen hebben direct effect op beschikbaarheid en waterverdeling; impact groter dan bij een passieve waterkering. | E5: Mogelijk groot | F5: Door de functionele rol van Panheel in zowel scheepvaart als waterverdeling zijn de gevolgen van lokale schade groter dan bij een passieve waterkering. | J5: Mogelijk groot | K5: Nog onbekend welke invloed de driver precies heeft; meer prioriteit om uit te zoeken
B6: Degradatie | C6: Algemene degradatie door verschillende processen die zorgen voor afname in sterkte van materialen in het complex | D6: Algemene materiaaldegradatie door ouderdom, belastinghistorie en interactie tussen beton, staal en water. | E6: Mogelijk groot | F6: Gezien de leeftijd van delen van het complex (oude en nieuwe kolk) ligt cumulatieve degradatie voor de hand en beïnvloedt dit direct de restlevensduur. | G6: Expert kennis TNO en RWS | J6: Groot | K6: Zeer relevante driver
A7: Klimaat- en natuurlijke processen | B7: Zeespiegelstijging | C7: Stijging van het gemiddelde zeeniveau | D7: De zeespiegelstijging bedraagt volgens huidige projecties circa +16 tot +38 cm in 2050 en +26 tot +124 cm in 2100 (afhankelijk van scenario). Sluizencomplex Panheel ligt diep landinwaarts en ondervindt geen directe invloed van zeespiegelstijging. | E7: Klein | F7: Zeespiegelstijging leidt niet tot directe wijziging van belastingen op Sluizencomplex Panheel, omdat het object niet wordt blootgesteld aan getij, zoutwater of mariene golfbelasting. Indirecte effecten zijn alleen mogelijk via langetermijnveranderingen in afvoerregimes en waterverdeling op systeemniveau, maar die worden primair gedreven door rivierafvoer en niet door zeespiegelstand. | G7: KNMI2023
B8: Verandering windklimaat | C8: Windsnelheid, windrichting, windextremen | D8: Voor Nederland wordt tot 2100 weinig verandering in gemiddelde windsnelheid en -richting verwacht. Wel kunnen extreme windstoten bij zware buien toenemen en komt wind uit zuidwestelijke richtingen mogelijk iets vaker voor. | E8: Klein | F8: Windbelasting is slechts zeer beperkte driver voor Sluizencomplex Panheel. Er zijn geen grote wateroppervlakken waarbij windopzet of windgolven maatgevend zijn voor ontwerp of functioneren. Wind kan alleen een operationele rol spelen (bijvoorbeeld bij bediening of scheepvaart), maar heeft geen significante invloed op constructieve veiligheid of veroudering. | G8: KNMI2023
B9: Verandering golfklimaat Noordzee | C9: Veranderingen in golfhoogte, - periode, en/of -richting | D9: Veranderingen in het golfklimaat zijn relevant voor kust- en estuariumobjecten. Voor Sluizencomplex Panheel is er geen golfbelasting vanuit zee en geen significante windgolfontwikkeling op het kanaal of in de kolk. | E9: Klein | F9: De hydraulische belasting bij Sluizencomplex Panheel wordt volledig gedomineerd door schutprocessen en scheepsbewegingen (schutgolven en scheepsgolven). Klimaatgedreven veranderingen in golfklimaat spelen hier geen rol. | G9: DeWinter2012; DeWinter2013;
B10: Toename piekafvoer Maas & Rijn | C10: Toename van jaarlijkse piekwaarden | D10: 2050 +5 tot +10%; 2100 -2 tot +30% in jaarlijkse maxima van het debiet in de Rijn. Voor de Maas is dit -8% - 2% en -8 - 20%. | E10: Mogelijk groot | F10: Hoewel Panheel geen primaire kering is, beïnvloeden hogere Maasafvoeren direct het kerend vermogen en de operationele belasting. | G10: Deltares2023
B11: Toename frequentie hoogwater Maas & Rijn | C11: Toename van kans hoogwater op rivieren | D11: Met name in de winter wordt verwacht dat er gemiddeld meer afvoer gaat stromen door de rivieren in Nederland. Voor de Maas is dit tot 10% meer in 2050 en 30% in 2100 en minder voor de overige. Voor de Rijn is dit tot 15% in 2050 en 35% in 2100. Dit is voor het meest extreme KNMI scenario Hoognat. Het is niet geheel duidelijk hoe dit doorvertaald tot toename in frequentie hoogwater bij de HIJK | E11: Mogelijk groot | F11: Hoewel Panheel geen primaire kering is, beïnvloeden hogere Maasafvoeren direct het kerend vermogen en de operationele belasting. | G11: Deltares2023
B12: Afname rivierafvoer (voornamelijk in de zomer) | C12: Afname van jaarlijks 7-daags minimum piekwaarden | D12: 2050 -5 tot -17%; 2100 -7 tot -32% voor 7-daags minimum op de Maas. | E12: Mogelijk groot | F12: Vergroot het belang van Panheel in waterverdeling richting Brabantse kanalen, inclusief inzet van pompen, waterbesparende maatregelen en mogelijke inzet van een aangepast schutregime. | G12: Deltares2023
B13: Toename frequentie laagwater Maas & Rijn | C13: Toename kans op laagwater op rivieren | D13: Geen exacte kwantificering van beschikbaar. Wel is de verwachting dat de gemiddelde zomer afvoer van de Maas afneemt: In 2050: 0 tot -13%, 2100: -5% tot -25% | E13: Mogelijk groot | F13: Vergroot het belang van Panheel in waterverdeling richting Brabantse kanalen, inclusief inzet van pompen, waterbesparende maatregelen en mogelijke inzet van een aangepast schutregime. | G13: Deltares2023
B14: Verandering neerslagpatronen | C14: Toename van de hoeveelheid (lokale) neerslag in het achterland leidt tot meer malen uit polders (bijv. hoosbuien) | D14: Winter 10 daags maximum per 10 jaar: 2050 verandering -2% tot +2%; 2100 verandering -2% tot +15%; Totale neerslag winter: 4-24% toename in 2100. Totale neerslag zomer: 2050 afname -2% tot -13%; 2100 afname -2% tot -29% | E14: Klein | F14: Effect indirect via waterbeheer; beperkt effect op constructieve belasting van de sluis. | G14: KNMI2023
B15: Toename luchttemperatuur | C15: Stijging van gemiddelde (en gem. dagminimum/maximum) | D15: Verschilt per scenario en per seizoen; 2050 +0,7 C tot +2,2 C; 2100 +0,7 C tot +5,4 C | E15: Mogelijk klein | F15: Een stijgende luchttemperatuur heeft geen directe invloed op de hydraulische of constructieve belastingen van Sluizencomplex Panheel. | G15: KNMI2023
B16: Verandering watertemperatuur | C16: Verandering van de gemiddelde temperatuur van het water rondom het complex | D16: Door opwarming van de aarde kan de watertemperatuur veranderen (in eerste instantie toenemen, als de golfstromen stoppen juist afnemen). | E16: Mogelijk klein | F16: Een hogere watertemperatuur kan invloed hebben op ecologie en waterkwaliteit, maar heeft geen maatgevende invloed op het functioneren of de veiligheid van Sluizencomplex Panheel. Eventuele effecten op materialen of installaties zijn beperkt en secundair. | G16: Expert kennis Deltares
B17: CO2-toename in de lucht | C17: Verandering CO2 concentratie in de lucht in parts per million (ppm) | D17: Alleen wereldwijde concentratie beschikbaar, huidig ~420 ppm; 2050 tot 600 ppm; 2100 tot 1100 ppm | E17: Mogelijk klein | F17: Een hogere CO₂‑concentratie kan op lange termijn bijdragen aan snellere carbonatatie van beton, maar voor Sluizencomplex Panheel wordt dit niet als zelfstandig maatgevend proces beschouwd. Het effect is beperkt en onderdeel van bredere klimaatgedreven degradatieprocessen. | G17: KNMI2023 TNO-rapport R10699
B18: Bodemdaling | C18: Het inklinken van de bodem en daarmee het zakken van het maaiveld | D18: Bodemdaling door inklinking van slappe ondergronden kan lokaal optreden, afhankelijk van bodemopbouw en grondwaterbeheer. | E18: Klein | F18: In de omgeving van Sluizencomplex Panheel is bodemdaling beperkt en relatief uniform, waardoor geen significante extra belasting of functieverlies van het complex wordt verwacht. Monitoring blijft wenselijk, maar bodemdaling is geen dominant aandachtspunt. | G18: Expert kennis RWS
B19: Verzilting | C19: Zoutindringing in zowel grondwater als oppervlaktewateren (door open estuarium of door sluizen) | D19: Verzilting treedt vooral op in open estuaria en kustgebieden. Sluizencomplex Panheel ligt landinwaarts en heeft geen directe zoutwaterinvloed. | E19: Klein | F19: Structurele zoutindringing speelt geen rol bij Sluizencomplex Panheel. Eventuele tijdelijke of lokale effecten hebben geen betekenis voor ontwerp, veiligheid of degradatie van het complex. | G19: Expert kennis Deltares
... B23: Verandering in biodiversiteit en ecosysteem | C23: Bijv. afname biodiversiteit en achteruitgang ecosysteem door veranderingen in waterkwaliteit of connectiviteit van gebieden | D23: Geen specifieke documentatie | E23: Mogelijk klein | F23: Veranderingen in waterkwaliteit en ecologie kunnen lokaal optreden, maar hebben geen directe invloed op het primaire functioneren van de sluis. Effecten zijn vooral relevant vanuit ecologisch beleid, niet vanuit objectveiligheid of beschikbaarheid. | G23: Expert kennis RWS
A24: Socio-economische ontwikkelingen | B24: Verandering scheepvaartverkeer | C24: Een toename, in zowel intensiteit als scheepsgrootte, maar ook veranderingen in transportstrategie en type vracht | D24: Veranderingen in intensiteit, scheepsgrootte, type lading en transportstrategie binnen de binnenvaart. Scheepvaartprognoses voor gebruik sluizencomplex Panheel zijn: 2040: -7% tot +33%, 2050: +13% tot +36%. | E24: Mogelijk groot | F24: Scheepvaart bepaalt direct de gebruiksbelasting van de sluis (schutfrequentie, mechanische belasting, slijtage). Dit is één van de belangrijkste drivers voor veroudering en beschikbaarheid van Sluizencomplex Panheel. | G24: Konings2026
B25: Verandering bebouwing en/of verhoging waarde bebouwd achterland | C25: Toename in aantal woningen in het binnendijks achterland en/of toename van de waarde van dit achterland. | D25: Toename van bebouwing en economische waarde van het binnendijks achterland. | E25: Klein | F25: Sluizencomplex Panheel is geen primaire waterkering. Een toename van de waarde van het achterland leidt niet automatisch tot strengere waterveiligheidseisen voor het object. | G25: Expert kennis RWS
B26: Verandering in benodigd beveiligingsniveau | C26: Cyber security threats en fysieke beveiliging | D26: Toename van cyberdreigingen en eisen aan fysieke beveiliging, mede door bediening op afstand. | E26: Groot | F26: De afhankelijkheid van digitale systemen maakt beveiliging cruciaal voor de continuïteit van de bediening en waterverdeling. Dit is een strategisch relevante driver. | G26: Expert kennis RWS
B27: Technische ontwikkelingen (software, materiaal) | C27: - | D27: Ontwikkelingen in automatisering, sensoren, materialen en datagedreven beheer. | E27: Middel | F27: Technische innovaties bieden kansen voor betere monitoring en levensduurverlenging, maar vraagt ook om aanpassing van beheer, kennis en organisatie. | G27: Expert kennis RWS
B28: Verandering situatie leverancier | C28: Onbeschikbaarheid noodzakelijk materiaal/materieel | D28: Afname beschikbaarheid van specifieke leveranciers, onderdelen of expertise. | E28: Middel | F28: Afhankelijkheid van unieke of verouderde componenten kan risico’s opleveren voor onderhoud en storingsherstel, vooral bij oudere installaties. | G28: Expert kennis RWS
B29: Vertrek/pensionering kennisdragers | C29: Kennis van personeel moet tijdig overgedragen kunnen worden om object specifieke kennis te borgen. Bij een groot verloop van personeel kan kennisoverdracht in het geding raken. | D29: Uitstroom van ervaren personeel met objectspecifieke kennis. | E29: Middel | F29: Gebrek aan overdracht van praktische en historische kennis kan leiden tot verhoogde faalrisico’s en minder effectief beheer. | G29: Expert kennis RWS
A30: Beleidskeuze | B30: Energietransitie | C30: Aanleg van winturbines en kabels | D30: Aanleg van windturbines, kabels en leidingen; verandering in energievoorziening van het object. | E30: Middel | F30: Geen directe invloed op veiligheid, maar wel relevant voor ruimtelijke inpassing, exploitatie en mogelijke aanpassing van energievoorziening. | G30: Expert kennis RWS
B31: Ecologische waarde watersysteem | C31: Aan weerszijden van het complex als ook de connectiviteit | D31: Toenemende aandacht voor ecologische kwaliteit en connectiviteit van watersystemen. | E31: Mogelijk klein | F31: Kan leiden tot aanvullende eisen of maatregelen (bijv. vismigratie), maar raakt het primaire functioneren van de sluis beperkt | G31: Expert kennis Deltares
B32: Verandering onderhoudsbudget | C32: Mogelijke verandering economisch beleid o.b.v. regeringsbesluiten betreffend RWS | D32: Wijzigingen in beschikbare middelen door economisch of politiek beleid. | E32: Middel | F32: Budgetveranderingen beïnvloeden onderhoudsfrequentie, risicohouding en keuzes rond levensduurverlenging. | G32: Rijksoverheid2024
B33: Stikstofbeleid | C33: Stikstofuitstoot bij het opereren en onderhouden van het complex | D33: Strengere regels voor stikstofemissies bij onderhoud en uitvoering. | E33: Klein | F33: Heeft vooral invloed op uitvoering en planning van werkzaamheden, niet op functioneren of veiligheid van de sluis. | G33: Deltares 2024a, expert judgement
B34: Verbod op gebruik materialen | C34: Mogelijk wordt de wetgeving aangescherpt voor het gebruik van bepaalde materialen, dat enkele materialen zal gaan verbieden (vanwege milieu en/of Arbo veiligheid) | D34: Aanscherping van wetgeving die bepaalde materialen verbiedt (milieu/Arbo). | E34: Klein | F34: Leidt tot alternatieve materiaalkeuzes, maar geen fundamentele aanpassing van het systeem. | G34: Expert kennis RWS
B35: Aanscherping arbo veiligheidsnormen | C35: Beperkingen voor de uitvoering van het onderhoud door aanscherpingen in de Arbo veiligheidseisen | D35: Strengere eisen aan arbeidsveiligheid bij inspectie en onderhoud. | E35: Middel | F35: Kan onderhoud complexer of duurder maken en planning beïnvloeden, maar raakt de objectfunctie niet direct. | G35: Expert kennis RWS
B36: Zoutindringing | C36: Mogelijke inzet van het complex bij tegengaan zoutindringing | D36: In gebieden waar verzilting van oppervlaktewateren optreedt of een risico is, kan een schutsluis worden ingezet om zoutindringing tegen te gaan. Gedacht kan worden aan een stremming waardoor verzilt water niet meer een bepaald waterlichaam kan binnendringen. | E36: Klein | F36: Sluizencomplex Panheel heeft geen structurele rol in zoutindringingsbeheer; zoutbelasting is geen maatgevende factor. | G36: Expert kennis Deltares, oa. KPZSS2023
B37: Aanpassing streef- en sluitpeilen | C37: Aanpassing peilen aan weerszijden van kunstwerk met name richting 2100. | D37: Door verandering van wateraanvoer of waterbeschikbaarheid kan worden gekozen om aangepaste peilgrenzen te hanteren in de toekomst. | E37: Klein | F37: Peilaanpassingen zijn denkbaar, maar leiden niet tot wezenlijk nieuwe belastingen of ontwerpvragen voor Panheel. | G37: Expert kennis RWS
B38: Vervanging complex | C38: Complex wordt vervangen door een andere waterkering en is niet meer nodig om de waterveiligheid te borgen | D38: Scenario waarin Sluizencomplex Panheel wordt vervangen of zijn functie verliest. | E38: Mogelijk groot | F38: Dit heeft grote consequenties voor investeringen, kennisontwikkeling en lange‑termijn beheerstrategie. | G38: Expert kennis RWS
B39: Heroverweging aantal kolken/ functiereductie sluis | C39: Ingegeven door energietransitie en besparingen, beperkt gebruik door scheepvaart, hoge onderhoudskosten, waterbeschikbaarheid of andere redenen, kan worden overwogen om een aantal onderdelen (waaronder kolken) terug te schalen. | D39: Binnen het operationeel team leven zorgen over de noodzaak van het aanhouden van twee schutkolken bij Sluizencomplex Panheel. | E39: Mogelijk groot | F39: Brede afweging van belangen en factoren kan leiden tot een andere keuze van de inrichting en inzet van verschillende onderdelen van het sluiscomplex | G39: Expert kennis RWS, Deltares
B40: Nieuwe systeemeisen en/of -inrichting | C40: Een herinrichting van het systeem en daarmee ook nieuwe eisen aan de sluis | D40: Herinrichting van vaarweg- of watersysteem met nieuwe functionele eisen. | E40: Middel | F40: Kan aanpassingen aan het complex vereisen, maar is sterk afhankelijk van beleidskeuzes en systeemontwikkeling. | G40: Expert kennis RWS
B41: Verlenging levensduur | C41: Verlengen van de levensduur (langer inzetten complex) | D41: Bewuste keuze om het complex langer te gebruiken dan oorspronkelijk voorzien. | E41: Middel | F41: Vraagt om betere kennis van degradatie, restlevensduur en adaptieve maatregelen — kernonderwerp voor de kennisagenda. | G41: Expert kennis TNO, RWS, Deltares
B42: Strengere waterveiligheidseis | C42: Strengere veiligheidseisen ivm bevolkingsgroei/vestiging van bedrijven in gebied of wensen vanuit achterliggende waterschap | D42: Mogelijke toename van eisen aan betrouwbaarheid (faalkans, niet‑sluiten). | E42: Middel | F42: Er geldt geen wettelijke faalkansnorm, maar maatschappelijke of bestuurlijke druk kan leiden tot hogere functionele eisen. | G42: RINK-analyse Panheel
... B44: Algemene beleidskeuzen op (inter)nationaal niveau | C44: Onder andere aandacht voor vismigratie evenals bijvoorbeeld druk op aangepast beleid na forse investering in ecologie | D44: Beleidswijzigingen rond ecologie, klimaatadaptatie, bereikbaarheid en waterbeheer. | E44: Middel | F44: Effecten op Sluizencomplex Panheel zijn onzeker, maar kunnen signficant effect hebben op het functioneren van (onderdelen van) Sluizencomplex Panheel. | G44: Expert kennis RWS

Sheet ETL_componentsniveau
J1: Klimatologische en natuurlijke ontwikkelingen | AB1: Socio-economische ontwikkelingen | AJ1: Beleidsmatige ontwikkelingen
B2: Autonome situatie | C2: Huidige eisen | D2: Huidige (en ontwerp) staat en constructieve beoordeling | E2: Vermoeiing | F2: Slijtage | G2: Schade (aanvaar, temperatuursinvloeden) | H2: Degradatie | I2: Drivers | J2: Zeespiegelstijging | K2: Verandering windklimaat | L2: Verandering golfklimaat | M2: Verandering in grondwaterstanden | N2: Toename piekafvoer Maas & Rijn (voornamellijk in winter) | O2: Toename frequentie hoogwater Maas & Rijn (voornamelijk in winter) | P2: Afname rivierafvoer Maas & Rijn (voornamelijk in zomer) | Q2: Toename frequentie laagwater Maas & Rijn (voornamelijk in zomer) | R2: Verandering Neerslagpatroon | S2: Verandering luchttemperatuur | T2: Verandering van watertemperatuur | U2: Toename CO2-gehalte in de lucht | V2: Bodemdaling | W2: Verzilting | X2: Verandering sedimenttransport en bodemerosie | Y2: Verandering afvoer verdeling rijn-maas monding | Z2: Verandering in bodemligging | AA2: Verandering biodiversiteit in ecosysteem | AB2: Verandering scheepvaartverkeer | AC2: Verandering bebouwing en/of verhoging waarde bebouwd achterland | AD2: Verandering in benodigd beveiligingsniveau | AE2: Technische ontwikkelingen (software, materiaal) | AF2: Verandering situatie leverancier | AG2: Verlies van kennisdragers (pensioenering/vertrek), zowel bij RWS, als aannemers, Deltares. | AH2: Energietransitie | AI2: Toename ecologische waarde sluis Panheel | AJ2: Verandering onderhoudsbudget Sluis Panheel | AK2: Stikstofbeleid | AL2: Verbod op gebruik materialen | AM2: Aanscherpen (arbo) veiligheidsnorm | AN2: Nieuwe normen constructieve veiligheid | AO2: Aanpassing schutpeil | AP2: Zoutindringing | AQ2: Vervanging Sluis Panheel | AR2: Heroverweging aantal kolken/ functiereductie sluis | AS2: Nieuwe systeemeisen en/of -inrichting | AT2: Verlenging levensduur Sluis Panheel | AU2: Strengere waterveiligheidseis Sluis Panheel | AV2: Algemene beleidskeuzes op (inter)nationaal niveau
A3: Algemeen | K3: Effect van veranderend windklimaat op Brabantse kanalen nog nader te bepalen, verwachting is dat dit geen significante invloed heeft. | P3: EF9: Veranderingen in het gestuwde Maaspeil en het stuwprogramma beïnvloeden waterstanden en hydraulische belastingen. Er is onzekerheid over de bandbreedte van deze waterstanden en de mogelijke effecten op voorhavens, bodem en oeverbescherming. | S3: A5: Mogelijke toename van strengere wintercondities kan leiden tot hogere ijsbelastingen op constructies en sluisdeuren. Het is onduidelijk in hoeverre hiermee rekening moet worden gehouden in ontwerp en beoordeling, of dat dit via beheermaatregelen kan worden opgevangen. | AE3: ET5, C13, C14, C23, C24, A16: Risico's voor veiligheid en beschikbaarheid bij spanningsuitval. Daarnaast is de beschikbaarheid en kwaliteit van ontwerp- en beheersdata vanuit RWS onvoldoende, wat leidt tot inefficiëntie en hogere kosten bij opdrachtnemers. | AF3: A12: Leveranciers en aannemers hebben moeite met wisselingen, maar dit vormt hier geen direct probleem. Wel is er behoefte aan betere borging en overdracht van kennis bij veranderingen van leverancier. | AH3: C15: vragen rond energiegebruik, noodstroom en spanningsuitval. | AL3: A7, C12: Ontwikkelingen richting biologisch afbreekbare smeermiddelen en duurzamere toepassingen in hydraulische systemen vragen om aandacht en monitoring. | AM3: In hoeverre leiden ruimtelijke beperkingen op het complex tot arbo- en veiligheidsrisico’s, en is de veiligheid voldoende geborgd? ( wordt meegenomen in het onderhoud (tb3)). | AN3: ET1, ET2, C11: Hoe kan de constructieve veiligheid van bestaande sluizen worden beoordeeld, gegeven veranderende normen, en welke eisen en toetsingskaders zijn daarbij passend? | AO3: Het waterpeil in de kanalen is momenteel vast, maar er is onzekerheid over toekomstige ontwikkelingen in waterpeilen en of deze van invloed zullen zijn op het functioneren van sluis Panheel. | AR3: Het sluizencomplex heeft als enige in het kanaal twee kolken. Er is de vraag in hoeverre exploitatie met één kolk mogelijk is en welke gevolgen dit heeft, terwijl er vanuit de scheepvaart momenteel geen knelpunten worden ervaren. | AS3: Het sluizencomplex heeft als enige in het kanaal twee kolken. Er is de vraag in hoeverre exploitatie met één kolk mogelijk is en welke gevolgen dit heeft, terwijl er vanuit de scheepvaart momenteel geen knelpunten worden ervaren. | AV3: EF9, C20, C21: Er is onzekerheid over een mogelijke toekomstige rol van het kanaal als route voor defensie of als wateraanvoerroute richting België. Hoewel huidige afspraken geen veranderingen voorzien, is onduidelijk wat de gevolgen zouden zijn voor sluis Panheel als dit wel wijzigt.
A4: Sluisonderdelen/-componenten
A5: Oude (noord) sluis | F5: Driver heeft geen invloed | G5: driver heeft geen invloed | H5: driver heeft geen invloed | J5: driver heeft geen invloed | K5: driver heeft geen invloed. Checkvraag: is er hier een verandering in windklimaat? | L5: driver heeft geen invloed | P5: EF9: Veranderingen in het gestuwde Maaspeil en het stuwprogramma beïnvloeden waterstanden en hydraulische belastingen. Er is onzekerheid over de bandbreedte van deze waterstanden en de mogelijke effecten op voorhavens, bodem en oeverbescherming. | S5: A5: Mogelijke toename van strengere wintercondities kan leiden tot hogere ijsbelastingen op constructies en sluisdeuren. Het is onduidelijk in hoeverre hiermee rekening moet worden gehouden in ontwerp en beoordeling, of dat dit via beheermaatregelen kan worden opgevangen. | U5: driver heeft geen invloed | W5: driver heeft geen invloed | X5: Aanwezig sediment in het kanaal vormt geen probleem. | Y5: driver heeft geen invloed | Z5: driver heeft geen invloed | AA5: Bevers zijn aanwezig en vormen met name een aandachtspunt voor het kanaal. Voor de sluis (incl. spaarbekkens) levert dit geen problemen op zolang deze in gebruik zijn; er is eerder een bever waargenomen aan de noordzijde. | AC5: driver heeft geen invloed | AI5: driver heeft geen invloed | AJ5: A8: Hoe beïnvloeden budgettekorten de risico’s, het kennisbehoud (bij RWS en aannemers) en de instandhouding van de sluis, en hoe bepaalt dit de prioriteit van het object binnen de totale vloot? | AK5: Stikstofbeleid heeft geen directe invloed op het onderhoud van de sluis. | AP5: driver heeft geen invloed | AQ5: ET6: De betonconstructie van de oude sluis vertoont scheurvorming en nadert het einde van de ontwerplevensduur (circa 9 jaar). Het is onzeker in hoeverre de sluis nog voldoet aan de gestelde eisen. | AT5: ET6: In hoeverre is verlenging van de levensduur van het sluizencomplex mogelijk en welke factoren zijn daarbij bepalend? | AU5: driver heeft geen invloed
A6: Beton constructies: fundering, sluishoofd & sluiskolk | D6: C1, C2, C3, ET1, ET3, C6, X14: Onzekerheid over staat van beton en moeilijk inspecteerbare onderdelen (o.a. schermen) door gebrek aan data → risico op afkeuring; behoefte aan proportioneel beoordelingskader (oude vs. nieuwe normen), met benutting van kennis van vergelijkbare kunstwerken. Onzekerheid bodemgesteldheid en betonconstructies: Misschien kans om topologie (bodemgesteldheid) te vergelijken met andere locaties waar meer kennis is? | M6: Grondwaterstanden vormen een onzekerheid: het effect van verhoogde of verlaagde grondwaterstanden is nog onvoldoende inzichtelijk. Dit wordt momenteel niet als zorg gezien, maar is wel relevant voor het functioneren van onderloopbaarheidsschermen. | N6: Een toename van wateraanvoer vanuit het achterland wordt niet als invloedrijk beschouwd voor het functioneren van het sluizencomplex: De verwachting is dat er geen extra scheepvaart bij stremming op de Maas komt en dat voldoende afvoercapaciteit blijft. | V6: Onzekerheid over toegankelijkheid van kabelkokers in de sluishoofden (onder de sluis) en risico op verzakking van kabels en leidingen. | X6: driver heeft geen invloed | AE6: C16, C17: Hoe kunnen reparatietechnieken en boorkernonderzoek worden geoptimaliseerd om het beheer en onderhoud van betonconstructies efficiënter uit te voeren? Behoefte aan inzicht in inspectie- en monitoringsmethoden en borging van veiligheid en beschikbaarheid. | AG6: Inspecties leveren waardevolle informatie op voor de beoordeling en het beheer van de constructie. | AK6: driver heeft geen invloed
A7: Spaarbekkens, riolen & nivelleermiddel | D7: EF21: Spaarbekkens functioneren niet maar zijn belangrijk voor waterbesparing (droogte) - functie vraag | M7: Driver heeft geen invloed | N7: Spaarbekkens verminderen het schutverlies met ca. 6.000 m³ per schutting. | R7: Inzet van de oude sluis in combinatie met spaarbekkens biedt de meest optimale waterbesparing bij droogte.
A8: Sluisdeuren | E8: C5, C6, ET4: Vermoeiing niet meegenomen in ontwerp; beheer via inspectie en reparatie, maar weinig inzicht in resterende levensduur en scheurgroei (ook afhankelijk van gebruik). Geldt ook voor bewegingswerken; geen reservedeuren nieuwe sluis. Bij de stalen sluisdeuren van met name de nieuwe sluis is sprake van vermoeiingsscheuren. Deze zijn recent hersteld, maar er is onvoldoende inzicht in de snelheid van sterkteafname over de tijd. | AB8: Variaties in het aantal bewegingen (te veel of te weinig) beïnvloeden de belasting; meer bewegingen verhogen het risico op vermoeiing, maar hangen niet direct samen met veranderingen in scheepvaartverkeer.
A9: Remmings en geleidewerken
A10: Aanvaarbeveiliging | D10: Er is ruime kennis en data beschikbaar over bodem, taluds en oeverbescherming, waaronder inspecties van de sluisbodem en multibeam-inmetingen. De levensduur van de bodembescherming blijft een aandachtspunt, maar vormt geen directe kennisvraag en is met aanvullend onderzoek te bepalen.
A11: Bodem- en oeverbescherming, talud | D11: Kennis is wel veel aanwezig. Bodem van de sluis is geinspecteerd (beton). Levensduur van bodembescherming? Multibeam inmetingen zijn er, beeld komt/is er dus. Niet persé kennisvragen hier, met onderzoek is hier uit te komen.
A12: Aandrijving en bewegingswerken | D12: Geen vragen. | AB12: Variaties in het aantal bewegingen (te veel of te weinig) beïnvloeden de belasting; meer bewegingen verhogen het risico op vermoeiing, maar hangen niet direct samen met veranderingen in scheepvaartverkeer. | AG12: De tandwielkast kon niet worden geïnspecteerd vanwege markttechnische beperkingen.
A13: Voorhavens
A14: Nieuwe (zuid) sluis: | P14: EF9 | S14: A5: Mogelijke toename van strengere wintercondities kan leiden tot hogere ijsbelastingen op constructies en sluisdeuren. Het is onduidelijk in hoeverre hiermee rekening moet worden gehouden in ontwerp en beoordeling, of dat dit via beheermaatregelen kan worden opgevangen.
A15: Beton constructies: fundering, sluishoofd & sluiskolk | D15: C1, C2, C3, ET2, C4 | AB15: Door grotere schepen wordt vaker gebruik gemaakt van de nieuwe sluis, wat leidt tot een toename in waterverbruik. | AE15: C16, C17: Hoe kunnen reparatietechnieken en boorkernonderzoek worden geoptimaliseerd om het beheer en onderhoud van betonconstructies efficiënter uit te voeren? Behoefte aan inzicht in inspectie- en monitoringsmethoden en borging van veiligheid en beschikbaarheid.
A16: Sluisdeuren | E16: C5, C6, ETL4: Vermoeiing niet meegenomen in ontwerp; beheer via inspectie en reparatie, maar weinig inzicht in resterende levensduur en scheurgroei (ook afhankelijk van gebruik). Geldt ook voor bewegingswerken; geen reservedeuren nieuwe sluis. Bij de stalen sluisdeuren van met name de nieuwe sluis is sprake van vermoeiingsscheuren. Deze zijn recent hersteld, maar er is onvoldoende inzicht in de snelheid van sterkteafname over de tijd. | AB16: De nieuwe sluis is ontworpen voor scheepstypen die hier niet meer voorkomen. Dit roept de vraag op of beide sluizen in de huidige vorm in stand moeten worden gehouden.
A17: Remmings en geleidewerken
A18: Aanvaarbeveiliging
A19: Bodem- en oeverbescherming, talud
A20: Aandrijving en bewegingswerken | D20: De mechanische aandrijving en hydraulische systemen functioneren betrouwbaar en zijn goed vervangbaar. De beoordeling van restlevensduur, met name van tandwielen, is echter onzeker: berekeningen zijn vaak conservatief en leiden tot onderschatting van de werkelijke levensduur, terwijl praktijkobservaties (zoals staat van tandvlakken) en veranderende belastingen een genuanceerder beeld geven.
A21: Voorhavens
A22: Gemaal: | D22: Er is eerder nagedacht over uitbreiding met een derde pomp om droogte op te vangen en redundantie te vergroten; dit zou de beschikbaarheid verbeteren, maar is momenteel niet gebudgetteerd. Restlevensduur pompen onbekend. | P22: EF9: Veranderingen in het gestuwde Maaspeil en het stuwprogramma beïnvloeden waterstanden en hydraulische belastingen. Er is onzekerheid over de bandbreedte van deze waterstanden en de mogelijke effecten op voorhavens, bodem en oeverbescherming. | S22: A5: Mogelijke toename van strengere wintercondities kan leiden tot hogere ijsbelastingen op constructies en sluisdeuren. Het is onduidelijk in hoeverre hiermee rekening moet worden gehouden in ontwerp en beoordeling, of dat dit via beheermaatregelen kan worden opgevangen. | AB22: Het niet functioneren van pompen kan leiden tot langdurige onbeschikbaarheid en wordt als calamiteit beschouwd, gezien eerdere situaties waarin met spoed een gemaal moest worden geplaatst toen de 2 pompen uitvielen. | AD22: Het gemaal is niet voorzien van beveiliging; bediening vindt op afstand plaats. Cybersecurity is hierbij meegenomen, maar toepassing daarvan op dit sluizencomplex is niet voorzien. | AE22: C10: Welke inspectietechnieken kunnen worden ingezet om de staat van moeilijk toegankelijke onderdelen van het gemaal betrouwbaar in beeld te brengen?
A23: Opstal (gemaal) + Pompkelder (beton) | D23: C7, EF24: Zorgen over betrouwbaarheid en levensduur pompen bij mogelijk intensiever gebruik; wens voor visvriendelijker gemaal. | AA23: EF24: Het gemaal is sterk visontvriendelijk en wordt regelmatig gebruikt, wat leidt tot vissterfte. Er is onduidelijkheid over de eisen vanuit natuur en KRW en de mogelijkheden om het gemaal visvriendelijker te maken. | AH23: C18: Toepassing van pompen als turbine (energieopwekking) is eerder verkend, maar blijkt in de huidige situatie niet haalbaar door trillingen en schade aan installaties. Tegelijk is er een generieke vraag naar de potentie van turbineren en de benodigde aanpassingen aan het systeem.
A24: Doorlaatkoker (gemaal) | D24: C9, C10: Wat is de actuele staat van de leidingen (kokers) van het gemaal naar de uitstroom en hoe kan deze betrouwbaar worden vastgesteld? | F24: Geen zorgen
A25: Terrein / objectoverstijgende voorzieningen: | D25: Toegankelijkheid bij calamiteiten is over het algemeen voldoende (weg en parkeerterrein aanwezig), maar het middengebied is lastiger bereikbaar door de spaarbekkens; dit vormt naar verwachting geen groot knelpunt.
A26: Bediening en besturing | AE26: A9: Bediening en besturing (o.a. camera’s, noodstop en lokale/mobiele bediening) worden steeds complexer en vragen om regelmatige vernieuwing. Er is een wens tot verdere standaardisatie, maar in de praktijk leidt dit tot knelpunten en blijft behoefte bestaan aan object-specifieke oplossingen. | AM26: A6
A27: Kerende constructies (specifiek voorhavens Maaszijde) | D27: Damwanden vallen onder de kerende constructies; er is geen kennisvraag. Inspectievraag: wat is de levensduur van de damwanden. Dit onderzoek loopt.
A28: Energievoorziening | D28: P: Aandachtspunt voor elektrische veiligheid; spanning en installaties van het gemaal dienen te worden geactualiseerd. -> Wat is de actuele elektrische veiligheid van het gemaal en welke maatregelen zijn nodig om te voldoen aan de huidige normen? | V28: Er is geen sprake van bodemdaling in het gebied; lokale verzakkingen kunnen wel optreden. Kabels en leidingen, evenals de laagspanningsinstallatie van het gemaal, worden naar verwachting meegenomen in het V&R-proces.
A29: Overige aspecten: | D29: P: Besturing inrichten: spuien als gemaal, richtlijnen machine veiligheid & RTC
A30: Operatie en B&O | D30: De technische complexiteit is hoog, maar B&O wordt voornamelijk belemmerd door contractuele, budgettaire en organisatorische factoren (beslismacht buiten RWS), waardoor terugkerend groot onderhoud stagneert en sterk afhankelijk is van politieke keuzes. Er is een wens tot verdere standaardisatie binnen B&O.
A31: Riolen (spui / omloop) | D31: Staat riolen (spui/omloop) afhankelijk van betonkwaliteit, scheuren en afdichting; onderwaterinspecties nodig, uitvoering grotendeels binnen eigen organisatie. | AE31: Drone-inspecties ontwikkelen zich snel; inzet van duikers wordt waar mogelijk vermeden.
A33: Algemeen / WVTTK | N33: A1: Klimaatscenario's vertalen naar hydraulische randvoorwaarden | AB33: A2: Klimaatscenario's vertalen naar lokale scenario's
E36: Legenda | G36: Driver niet aanwezig | I36: Invloed driver beperkt of | N36: Invloed driver is | R36: Heeft invloed, kennisvraag
G37: of heeft geen invloed | I37: op te lossen binnen BenO | N37: een kennisvraag | R37: wanneer en oplossingsrichtingen

Sheet EFL sluizen
K1: Klimatologische en natuurlijke ontwikkelingen | AB1: Socio-economische ontwikkelingen | AJ1: Beleidsmatige ontwikkelingen
A2: Categorie | B2: Functies | C2: Autonome situatie | D2: Huidige eisen | E2: Huidige (en ontwerp) staat en constructieve beoordeling | F2: Vermoeiing | G2: Slijtage | H2: Schade (aanvaar, temperatuursinvloeden) | I2: Degradatie | J2: Drivers | K2: Zeespiegelstijging | L2: Verandering windklimaat | M2: Verandering golfklimaat | N2: Toename piekafvoer Maas & Rijn | O2: Toename frequentie hoogwater Maas & Rijn | P2: Afname rivierafvoer Maas & Rijn (voornamelijk in zomer) | Q2: Toename frequentie laagwater Maas & Rijn (voornamelijk in zomer) | R2: Verandering Neerslagpatroon | S2: Verandering van luchttemperatuur | T2: Verandering van watertemperatuur | U2: Toename CO2-gehalte in de lucht | V2: Bodemdaling | W2: Verzilting | X2: Verandering sedimenttransport en bodemerosie | Y2: Verandering afvoer verdeling rijn-maas monding | Z2: Verandering in bodemligging | AA2: Verandering (eisen aan) biodiversiteit in ecosysteem | AB2: Verandering scheepvaartverkeer | AC2: Verandering bebouwing en/of verhoging waarde bebouwd achterland | AD2: Verandering in benodigd veiligheidsniveau | AE2: Technische ontwikkelingen (software, materiaal) | AF2: Verandering situatie leverancier | AG2: Verlies van kennisdragers (pensioenering/vertrek), zowel bij RWS, als aannemers, Deltares. | AH2: Energietransitie | AI2: Toename ecologische waarde sluis Panheel | AJ2: Verandering onderhoudsbudget Sluis Panheel | AK2: Stikstofbeleid | AL2: Verbod op gebruik materialen | AM2: Aanscherping arbo veiligheidsnorm | AN2: Aanpassing sluitpeil | AO2: Zoutindringing | AP2: Vervanging sluis Panheel | AQ2: Heroverweging aantal kolken/ functiereductie sluis | AR2: Nieuwe systeemeisen en/of -inrichting | AS2: Verlenging levensduur sluis Panheel | AT2: Strengere waterveiligheidseis sluis Panheel | AU2: Algemene beleidskeuzes op (inter)nationaal niveau | AV2: duurzaamheid, beschikbaarheid materialen
A4: Algemeen / integraal | G4: driver heeft geen invloed | H4: driver heeft geen invloed | I4: driver heeft geen invloed | J4: EF1, EF2, EF22: integraal plan voor de lange termijn, meer dan 30 jaar vooruit, ontbreekt. Hoe kunnen we keuzemomenten en adaptatiepaden identificeren en rekening houden met de langere termijn bij keuzes op de kortere termijn? Inclusief budgetverminderingen, kennisbehoud. | K4: driver heeft geen invloed | L4: driver heeft geen invloed | M4: driver heeft geen invloed | O4: driver heeft geen invloed | R4: driver heeft geen invloed | S4: driver heeft geen invloed | T4: driver heeft geen invloed | U4: driver heeft geen invloed | V4: driver heeft geen invloed | W4: driver heeft geen invloed | X4: driver heeft geen invloed | Y4: driver heeft geen invloed | Z4: driver heeft geen invloed | AA4: Bij verbouwing en grootscheepse aanpassingen: Inventarisatie omliggende natuur nodig. | AC4: driver heeft geen invloed | AD4: driver heeft geen invloed | AE4: Hoe kun je AI inzetten op een betrouwbare manier? Hoe zet je de experts in om de AI uitkomsten te checken/valideren? Ook AI-ontwikkeling kan een gevaar zijn, want nieuwe medewerkers/nieuwe generatie vertrouwen daar veel op. Andere kant ook een kans natuurlijk qua data. | AF4: A10: Hoe zorg je voor kennisniveau op de markt op niveau en kenniscontinuiteit bij marktpartijen? | AG4: A11, A12. A13, A14, A15: Hoe behoud je de benodige kennis voor B&O en vervanging/renovatie/vernieuwing binnen de organisatie (RWS)? RWS collega's met echt inhoudelijke kennis van zaken worden minder, echt een ding voor toetsing van stukken opdrachtnemers of aannemers. KV: Kennisbehoud bij overige partners (bijvoorbeeld Wallonie): Samenwerking in de toekomst onzeker: Maas afvoerverdrag treedt in werking bij laag water, geen verdrag met Wallonië. Naleving gaat wel goed nu, als er nieuwe mensen zijn is er wel een risico misschien. Voor oude sluizen neemt de beschikbaarheid van materialen en specifieke kennis af, waardoor vervanging niet altijd één-op-één mogelijk is en risico’s voor de beschikbaarheid ontstaan. Kennis is bovendien geconcentreerd bij een beperkt aantal personen. De externe capaciteit in de aannemerij is een aandachtspunt; er zijn weinig onderhoudscontracten, terwijl de vraag naar uitvoering en onderhoud naar verwachting zal toenemen. | AJ4: EF1, C19: Visie welke functies op welk niveau behouden / loslaten bij afnemend onderhoudsbudget? | AL4: driver heeft geen invloed | AM4: driver heeft geen invloed | AN4: driver heeft geen invloed | AO4: driver heeft geen invloed | AP4: driver heeft geen invloed | AQ4: driver heeft geen invloed | AR4: EF9: Veranderingen in het gestuwde Maaspeil en het stuwprogramma beïnvloeden waterstanden en hydraulische belastingen. Er is onzekerheid over de bandbreedte van deze waterstanden en de mogelijke effecten op voorhavens, bodem en oeverbescherming.
